Workbook
Name Slicer_Education_Name: #N/A
Name Slicer_Experience_Level: #N/A
Name Slicer_Gender_Name: #N/A
Name Slicer_Hiring_Decision_Name: #N/A
Name Slicer_Readiness_Category: #N/A

Sheet Sheet1
A3: Row Labels | B3: Count of Hiring_Decision_Name
A4: Hired | B4: 228
A5: Not Hired | B5: 510
A6: Grand Total | B6: 738

Sheet Sheet2
A3: Gender_Name | B3: Count of Hiring_Decision_Name
A4: Female | B4: 738
A5: Grand Total | B5: 738
H10: hjghj
H11: jkk

Sheet Sheet3
A3: Row Labels | B3: Count of Candidate_id
A4: Developing | B4: 375
A5: Job Ready | B5: 34
A6: Needs Improvement | B6: 329
A7: Grand Total | B7: 738

Sheet Sheet4
A3: Row Labels | B3: Count of Candidate_id
A4: Entry Level | B4: 136
A5: Mid Level | B5: 175
A6: Senior Level | B6: 427
A7: Grand Total | B7: 738

Sheet Sheet5
A3: Row Labels | B3: Count of Candidate_id
A4: Bachelor's Type 1 | B4: 147
A5: Bachelor's Type 2 | B5: 363
A6: Master's | B6: 164
A7: PhD | B7: 64
A8: Grand Total | B8: 738

Sheet Sheet6
A3: Row Labels | B3: Count of Candidate_id
A4: Interview | B4: 253
A5: Personality | B5: 235
A6: Technical Skills | B6: 250
A7: Grand Total | B7: 738

Sheet Sheet7
A3: Row Labels | B3: Count of Candidate_id
A4: Interview Preparation | B4: 256
A5: Personality & Communication | B5: 236
A6: Technical Skills | B6: 246
A7: Grand Total | B7: 738

Sheet recruitment_data
A1: Age | B1: Gender | C1: EducationLevel | D1: ExperienceYears | E1: PreviousCompanies | F1: DistanceFromCompany | G1: InterviewScore | H1: SkillScore | I1: PersonalityScore | J1: RecruitmentStrategy | K1: HiringDecision | L1: Candidate_id | M1: Gender_Name | N1: Education_Name | O1: Experience_Level | P1: Interview_Performance | Q1: Technical_Skill_Level | R1: Personality_Level | S1: Hiring_Decision_Name | T1: Candidate_Readiness_Score | U1: Readiness_Category | V1: Primary Strength | W1: Primary Gap | X1: Improvement Recommendation
A2: 26 | B2: 1 | C2: 2 | D2: 0 | E2: 3 | F2: 26.783828 | G2: 48 | H2: 78 | I2: 91 | J2: 1 | K2: 1 | L2: ="C"&TEXT(ROW()-1,"000") -> C001 | M2: =IF(B2=0,"Male","Female") -> Female | N2: =IF(C2=1,"Bachelor's Type 1",IF(C2=2,"Bachelor's Type 2",IF(C2=3,"Master's","PhD"))) -> Bachelor's Type 2 | O2: =IF(D2<=2,"Entry Level",IF(D2<=6,"Mid Level","Senior Level")) -> Entry Level | P2: =IF(G2<50,"Low",IF(G2<75,"Average","Strong")) -> Low | Q2: =IF(H2<50,"Beginner",IF(H2<75,"Intermediate","Advanced")) -> Advanced | R2: =IF(I2<50,"Needs Improvement",IF(I2<75,"Good","Strong")) -> Strong | S2: =IF(K2=1,"Hired","Not Hired") -> Hired | T2: =ROUND((G2*30%)+(H2*30%)+(I2*20%)+((D2/15)*100*15%)+(IF(C2<=2,50,IF(C2=3,75,100))*5%),0) -> 59 | U2: =IF(T2<50,"Needs Improvement",IF(T2<75,"Developing","Job Ready")) -> Developing | V2: =IF(AND(G2>=H2,G2>=I2),"Interview",IF(H2>=I2,"Technical Skills","Personality")) -> Personality | W2: =IF(AND(G2<=H2,G2<=I2),"Interview Preparation",IF(H2<=I2,"Technical Skills","Personality & Communication")) -> Interview Preparation | X2: =IF(W2="Interview Preparation","Improve interview preparation and communication",IF(W2="Technical Skills","Strengthen technical skills and practical knowledge","Work on communication and personality development")) -> Improve interview preparation and communication
A3: 39 | B3: 1 | C3: 4 | D3: 12 | E3: 3 | F3: 25.862694 | G3: 35 | H3: 68 | I3: 80 | J3: 2 | K3: 1 | L3: ="C"&TEXT(ROW()-1,"000") -> C002 | M3: =IF(B3=0,"Male","Female") -> Female | N3: =IF(C3=1,"Bachelor's Type 1",IF(C3=2,"Bachelor's Type 2",IF(C3=3,"Master's","PhD"))) -> PhD | O3: =IF(D3<=2,"Entry Level",IF(D3<=6,"Mid Level","Senior Level")) -> Senior Level | P3: =IF(G3<50,"Low",IF(G3<75,"Average","Strong")) -> Low | Q3: =IF(H3<50,"Beginner",IF(H3<75,"Intermediate","Advanced")) -> Intermediate | R3: =IF(I3<50,"Needs Improvement",IF(I3<75,"Good","Strong")) -> Strong | S3: =IF(K3=1,"Hired","Not Hired") -> Hired | T3: =ROUND((G3*30%)+(H3*30%)+(I3*20%)+((D3/15)*100*15%)+(IF(C3<=2,50,IF(C3=3,75,100))*5%),0) -> 64 | U3: =IF(T3<50,"Needs Improvement",IF(T3<75,"Developing","Job Ready")) -> Developing | V3: =IF(AND(G3>=H3,G3>=I3),"Interview",IF(H3>=I3,"Technical Skills","Personality")) -> Personality | W3: =IF(AND(G3<=H3,G3<=I3),"Interview Preparation",IF(H3<=I3,"Technical Skills","Personality & Communication")) -> Interview Preparation | X3: =IF(W3="Interview Preparation","Improve interview preparation and communication",IF(W3="Technical Skills","Strengthen technical skills and practical knowledge","Work on communication and personality development")) -> Improve interview preparation and communication
A4: 48 | B4: 0 | C4: 2 | D4: 3 | E4: 2 | F4: 9.9208048 | G4: 20 | H4: 67 | I4: 13 | J4: 2 | K4: 0 | L4: ="C"&TEXT(ROW()-1,"000") -> C003 | M4: =IF(B4=0,"Male","Female") -> Male | N4: =IF(C4=1,"Bachelor's Type 1",IF(C4=2,"Bachelor's Type 2",IF(C4=3,"Master's","PhD"))) -> Bachelor's Type 2 | O4: =IF(D4<=2,"Entry Level",IF(D4<=6,"Mid Level","Senior Level")) -> Mid Level | P4: =IF(G4<50,"Low",IF(G4<75,"Average","Strong")) -> Low | Q4: =IF(H4<50,"Beginner",IF(H4<75,"Intermediate","Advanced")) -> Intermediate | R4: =IF(I4<50,"Needs Improvement",IF(I4<75,"Good","Strong")) -> Needs Improvement | S4: =IF(K4=1,"Hired","Not Hired") -> Not Hired | T4: =ROUND((G4*30%)+(H4*30%)+(I4*20%)+((D4/15)*100*15%)+(IF(C4<=2,50,IF(C4=3,75,100))*5%),0) -> 34 | U4: =IF(T4<50,"Needs Improvement",IF(T4<75,"Developing","Job Ready")) -> Needs Improvement | V4: =IF(AND(G4>=H4,G4>=I4),"Interview",IF(H4>=I4,"Technical Skills","Personality")) -> Technical Skills | W4: =IF(AND(G4<=H4,G4<=I4),"Interview Preparation",IF(H4<=I4,"Technical Skills","Personality & Communication")) -> Personality & Communication | X4: =IF(W4="Interview Preparation","Improve interview preparation and communication",IF(W4="Technical Skills","Strengthen technical skills and practical knowledge","Work on communication and personality development")) -> Work on communication and personality development
A5: 34 | B5: 1 | C5: 2 | D5: 5 | E5: 2 | F5: 6.4077507 | G5: 36 | H5: 27 | I5: 70 | J5: 3 | K5: 0 | L5: ="C"&TEXT(ROW()-1,"000") -> C004 | M5: =IF(B5=0,"Male","Female") -> Female | N5: =IF(C5=1,"Bachelor's Type 1",IF(C5=2,"Bachelor's Type 2",IF(C5=3,"Master's","PhD"))) -> Bachelor's Type 2 | O5: =IF(D5<=2,"Entry Level",IF(D5<=6,"Mid Level","Senior Level")) -> Mid Level | P5: =IF(G5<50,"Low",IF(G5<75,"Average","Strong")) -> Low | Q5: =IF(H5<50,"Beginner",IF(H5<75,"Intermediate","Advanced")) -> Beginner | R5: =IF(I5<50,"Needs Improvement",IF(I5<75,"Good","Strong")) -> Good | S5: =IF(K5=1,"Hired","Not Hired") -> Not Hired | T5: =ROUND((G5*30%)+(H5*30%)+(I5*20%)+((D5/15)*100*15%)+(IF(C5<=2,50,IF(C5=3,75,100))*5%),0) -> 40 | U5: =IF(T5<50,"Needs Improvement",IF(T5<75,"Developing","Job Ready")) -> Needs Improvement | V5: =IF(AND(G5>=H5,G5>=I5),"Interview",IF(H5>=I5,"Technical Skills","Personality")) -> Personality | W5: =IF(AND(G5<=H5,G5<=I5),"Interview Preparation",IF(H5<=I5,"Technical Skills","Personality & Communication")) -> Technical Skills | X5: =IF(W5="Interview Preparation","Improve interview preparation and communication",IF(W5="Technical Skills","Strengthen technical skills and practical knowledge","Work on communication and personality development")) -> Strengthen technical skills and practical knowledge
A6: 30 | B6: 0 | C6: 1 | D6: 6 | E6: 1 | F6: 43.105343 | G6: 23 | H6: 52 | I6: 85 | J6: 2 | K6: 0 | L6: ="C"&TEXT(ROW()-1,"000") -> C005 | M6: =IF(B6=0,"Male","Female") -> Male | N6: =IF(C6=1,"Bachelor's Type 1",IF(C6=2,"Bachelor's Type 2",IF(C6=3,"Master's","PhD"))) -> Bachelor's Type 1 | O6: =IF(D6<=2,"Entry Level",IF(D6<=6,"Mid Level","Senior Level")) -> Mid Level | P6: =IF(G6<50,"Low",IF(G6<75,"Average","Strong")) -> Low | Q6: =IF(H6<50,"Beginner",IF(H6<75,"Intermediate","Advanced")) -> Intermediate | R6: =IF(I6<50,"Needs Improvement",IF(I6<75,"Good","Strong")) -> Strong | S6: =IF(K6=1,"Hired","Not Hired") -> Not Hired | T6: =ROUND((G6*30%)+(H6*30%)+(I6*20%)+((D6/15)*100*15%)+(IF(C6<=2,50,IF(C6=3,75,100))*5%),0) -> 48 | U6: =IF(T6<50,"Needs Improvement",IF(T6<75,"Developing","Job Ready")) -> Needs Improvement | V6: =IF(AND(G6>=H6,G6>=I6),"Interview",IF(H6>=I6,"Technical Skills","Personality")) -> Personality | W6: =IF(AND(G6<=H6,G6<=I6),"Interview Preparation",IF(H6<=I6,"Technical Skills","Personality & Communication")) -> Interview Preparation | X6: =IF(W6="Interview Preparation","Improve interview preparation and communication",IF(W6="Technical Skills","Strengthen technical skills and practical knowledge","Work on communication and personality development")) -> Improve interview preparation and communication
A7: 27 | B7: 0 | C7: 3 | D7: 14 | E7: 4 | F7: 31.706659 | G7: 54 | H7: 50 | I7: 50 | J7: 1 | K7: 1 | L7: ="C"&TEXT(ROW()-1,"000") -> C006 | M7: =IF(B7=0,"Male","Female") -> Male | N7: =IF(C7=1,"Bachelor's Type 1",IF(C7=2,"Bachelor's Type 2",IF(C7=3,"Master's","PhD"))) -> Master's | O7: =IF(D7<=2,"Entry Level",IF(D7<=6,"Mid Level","Senior Level")) -> Senior Level | P7: =IF(G7<50,"Low",IF(G7<75,"Average","Strong")) -> Average | Q7: =IF(H7<50,"Beginner",IF(H7<75,"Intermediate","Advanced")) -> Intermediate | R7: =IF(I7<50,"Needs Improvement",IF(I7<75,"Good","Strong")) -> Good | S7: =IF(K7=1,"Hired","Not Hired") -> Hired | T7: =ROUND((G7*30%)+(H7*30%)+(I7*20%)+((D7/15)*100*15%)+(IF(C7<=2,50,IF(C7=3,75,100))*5%),0) -> 59 | U7: =IF(T7<50,"Needs Improvement",IF(T7<75,"Developing","Job Ready")) -> Developing | V7: =IF(AND(G7>=H7,G7>=I7),"Interview",IF(H7>=I7,"Technical Skills","Personality")) -> Interview | W7: =IF(AND(G7<=H7,G7<=I7),"Interview Preparation",IF(H7<=I7,"Technical Skills","Personality & Communication")) -> Technical Skills | X7: =IF(W7="Interview Preparation","Improve interview preparation and communication",IF(W7="Technical Skills","Strengthen technical skills and practical knowledge","Work on communication and personality development")) -> Strengthen technical skills and practical knowledge
A8: 48 | B8: 0 | C8: 2 | D8: 6 | E8: 1 | F8: 17.291229 | G8: 24 | H8: 52 | I8: 64 | J8: 3 | K8: 0 | L8: ="C"&TEXT(ROW()-1,"000") -> C007 | M8: =IF(B8=0,"Male","Female") -> Male | N8: =IF(C8=1,"Bachelor's Type 1",IF(C8=2,"Bachelor's Type 2",IF(C8=3,"Master's","PhD"))) -> Bachelor's Type 2 | O8: =IF(D8<=2,"Entry Level",IF(D8<=6,"Mid Level","Senior Level")) -> Mid Level | P8: =IF(G8<50,"Low",IF(G8<75,"Average","Strong")) -> Low | Q8: =IF(H8<50,"Beginner",IF(H8<75,"Intermediate","Advanced")) -> Intermediate | R8: =IF(I8<50,"Needs Improvement",IF(I8<75,"Good","Strong")) -> Good | S8: =IF(K8=1,"Hired","Not Hired") -> Not Hired | T8: =ROUND((G8*30%)+(H8*30%)+(I8*20%)+((D8/15)*100*15%)+(IF(C8<=2,50,IF(C8=3,75,100))*5%),0) -> 44 | U8: =IF(T8<50,"Needs Improvement",IF(T8<75,"Developing","Job Ready")) -> Needs Improvement | V8: =IF(AND(G8>=H8,G8>=I8),"Interview",IF(H8>=I8,"Technical Skills","Personality")) -> Personality | W8: =IF(AND(G8<=H8,G8<=I8),"Interview Preparation",IF(H8<=I8,"Technical Skills","Personality & Communication")) -> Interview Preparation | X8: =IF(W8="Interview Preparation","Improve interview preparation and communication",IF(W8="Technical Skills","Strengthen technical skills and practical knowledge","Work on communication and personality development")) -> Improve interview preparation and communication
A9: 40 | B9: 0 | C9: 4 | D9: 13 | E9: 3 | F9: 10.586811 | G9: 6 | H9: 3 | I9: 92 | J9: 3 | K9: 0 | L9: ="C"&TEXT(ROW()-1,"000") -> C008 | M9: =IF(B9=0,"Male","Female") -> Male | N9: =IF(C9=1,"Bachelor's Type 1",IF(C9=2,"Bachelor's Type 2",IF(C9=3,"Master's","PhD"))) -> PhD | O9: =IF(D9<=2,"Entry Level",IF(D9<=6,"Mid Level","Senior Level")) -> Senior Level | P9: =IF(G9<50,"Low",IF(G9<75,"Average","Strong")) -> Low | Q9: =IF(H9<50,"Beginner",IF(H9<75,"Intermediate","Advanced")) -> Beginner | R9: =IF(I9<50,"Needs Improvement",IF(I9<75,"Good","Strong")) -> Strong | S9: =IF(K9=1,"Hired","Not Hired") -> Not Hired | T9: =ROUND((G9*30%)+(H9*30%)+(I9*20%)+((D9/15)*100*15%)+(IF(C9<=2,50,IF(C9=3,75,100))*5%),0) -> 39 | U9: =IF(T9<50,"Needs Improvement",IF(T9<75,"Developing","Job Ready")) -> Needs Improvement | V9: =IF(AND(G9>=H9,G9>=I9),"Interview",IF(H9>=I9,"Technical Skills","Personality")) -> Personality | W9: =IF(AND(G9<=H9,G9<=I9),"Interview Preparation",IF(H9<=I9,"Technical Skills","Personality & Communication")) -> Technical Skills | X9: =IF(W9="Interview Preparation","Improve interview preparation and communication",IF(W9="Technical Skills","Strengthen technical skills and practical knowledge","Work on communication and personality development")) -> Strengthen technical skills and practical knowledge
A10: 26 | B10: 1 | C10: 3 | D10: 6 | E10: 5 | F10: 28.774864 | G10: 80 | H10: 78 | I10: 51 | J10: 1 | K10: 1 | L10: ="C"&TEXT(ROW()-1,"000") -> C009 | M10: =IF(B10=0,"Male","Female") -> Female | N10: =IF(C10=1,"Bachelor's Type 1",IF(C10=2,"Bachelor's Type 2",IF(C10=3,"Master's","PhD"))) -> Master's | O10: =IF(D10<=2,"Entry Level",IF(D10<=6,"Mid Level","Senior Level")) -> Mid Level | P10: =IF(G10<50,"Low",IF(G10<75,"Average","Strong")) -> Strong | Q10: =IF(H10<50,"Beginner",IF(H10<75,"Intermediate","Advanced")) -> Advanced | R10: =IF(I10<50,"Needs Improvement",IF(I10<75,"Good","Strong")) -> Good | S10: =IF(K10=1,"Hired","Not Hired") -> Hired | T10: =ROUND((G10*30%)+(H10*30%)+(I10*20%)+((D10/15)*100*15%)+(IF(C10<=2,50,IF(C10=3,75,100))*5%),0) -> 67 | U10: =IF(T10<50,"Needs Improvement",IF(T10<75,"Developing","Job Ready")) -> Developing | V10: =IF(AND(G10>=H10,G10>=I10),"Interview",IF(H10>=I10,"Technical Skills","Personality")) -> Interview | W10: =IF(AND(G10<=H10,G10<=I10),"Interview Preparation",IF(H10<=I10,"Technical Skills","Personality & Communication")) -> Personality & Communication | X10: =IF(W10="Interview Preparation","Improve interview preparation and communication",IF(W10="Technical Skills","Strengthen technical skills and practical knowledge","Work on communication and personality development")) -> Work on communication and personality development
A11: 45 | B11: 1 | C11: 2 | D11: 2 | E11: 5 | F11: 30.195964 | G11: 92 | H11: 16 | I11: 94 | J11: 3 | K11: 0 | L11: ="C"&TEXT(ROW()-1,"000") -> C010 | M11: =IF(B11=0,"Male","Female") -> Female | N11: =IF(C11=1,"Bachelor's Type 1",IF(C11=2,"Bachelor's Type 2",IF(C11=3,"Master's","PhD"))) -> Bachelor's Type 2 | O11: =IF(D11<=2,"Entry Level",IF(D11<=6,"Mid Level","Senior Level")) -> Entry Level | P11: =IF(G11<50,"Low",IF(G11<75,"Average","Strong")) -> Strong | Q11: =IF(H11<50,"Beginner",IF(H11<75,"Intermediate","Advanced")) -> Beginner | R11: =IF(I11<50,"Needs Improvement",IF(I11<75,"Good","Strong")) -> Strong | S11: =IF(K11=1,"Hired","Not Hired") -> Not Hired | T11: =ROUND((G11*30%)+(H11*30%)+(I11*20%)+((D11/15)*100*15%)+(IF(C11<=2,50,IF(C11=3,75,100))*5%),0) -> 56 | U11: =IF(T11<50,"Needs Improvement",IF(T11<75,"Developing","Job Ready")) -> Developing | V11: =IF(AND(G11>=H11,G11>=I11),"Interview",IF(H11>=I11,"Technical Skills","Personality")) -> Personality | W11: =IF(AND(G11<=H11,G11<=I11),"Interview Preparation",IF(H11<=I11,"Technical Skills","Personality & Communication")) -> Technical Skills | X11: =IF(W11="Interview Preparation","Improve interview preparation and communication",IF(W11="Technical Skills","Strengthen technical skills and practical knowledge","Work on communication and personality development")) -> Strengthen technical skills and practical knowledge
A12: 38 | B12: 1 | C12: 1 | D12: 15 | E12: 2 | F12: 11.34968 | G12: 93 | H12: 66 | I12: 29 | J12: 2 | K12: 0 | L12: ="C"&TEXT(ROW()-1,"000") -> C011 | M12: =IF(B12=0,"Male","Female") -> Female | N12: =IF(C12=1,"Bachelor's Type 1",IF(C12=2,"Bachelor's Type 2",IF(C12=3,"Master's","PhD"))) -> Bachelor's Type 1 | O12: =IF(D12<=2,"Entry Level",IF(D12<=6,"Mid Level","Senior Level")) -> Senior Level | P12: =IF(G12<50,"Low",IF(G12<75,"Average","Strong")) -> Strong | Q12: =IF(H12<50,"Beginner",IF(H12<75,"Intermediate","Advanced")) -> Intermediate | R12: =IF(I12<50,"Needs Improvement",IF(I12<75,"Good","Strong")) -> Needs Improvement | S12: =IF(K12=1,"Hired","Not Hired") -> Not Hired | T12: =ROUND((G12*30%)+(H12*30%)+(I12*20%)+((D12/15)*100*15%)+(IF(C12<=2,50,IF(C12=3,75,100))*5%),0) -> 71 | U12: =IF(T12<50,"Needs Improvement",IF(T12<75,"Developing","Job Ready")) -> Developing | V12: =IF(AND(G12>=H12,G12>=I12),"Interview",IF(H12>=I12,"Technical Skills","Personality")) -> Interview | W12: =IF(AND(G12<=H12,G12<=I12),"Interview Preparation",IF(H12<=I12,"Technical Skills","Personality & Communication")) -> Personality & Communication | X12: =IF(W12="Interview Preparation","Improve interview preparation and communication",IF(W12="Technical Skills","Strengthen technical skills and practical knowledge","Work on communication and personality development")) -> Work on communication and personality development
A13: 42 | B13: 0 | C13: 3 | D13: 5 | E13: 5 | F13: 43.570287 | G13: 70 | H13: 73 | I13: 56 | J13: 2 | K13: 0 | L13: ="C"&TEXT(ROW()-1,"000") -> C012 | M13: =IF(B13=0,"Male","Female") -> Male | N13: =IF(C13=1,"Bachelor's Type 1",IF(C13=2,"Bachelor's Type 2",IF(C13=3,"Master's","PhD"))) -> Master's | O13: =IF(D13<=2,"Entry Level",IF(D13<=6,"Mid Level","Senior Level")) -> Mid Level | P13: =IF(G13<50,"Low",IF(G13<75,"Average","Strong")) -> Average | Q13: =IF(H13<50,"Beginner",IF(H13<75,"Intermediate","Advanced")) -> Intermediate | R13: =IF(I13<50,"Needs Improvement",IF(I13<75,"Good","Strong")) -> Good | S13: =IF(K13=1,"Hired","Not Hired") -> Not Hired | T13: =ROUND((G13*30%)+(H13*30%)+(I13*20%)+((D13/15)*100*15%)+(IF(C13<=2,50,IF(C13=3,75,100))*5%),0) -> 63 | U13: =IF(T13<50,"Needs Improvement",IF(T13<75,"Developing","Job Ready")) -> Developing | V13: =IF(AND(G13>=H13,G13>=I13),"Interview",IF(H13>=I13,"Technical Skills","Personality")) -> Technical Skills | W13: =IF(AND(G13<=H13,G13<=I13),"Interview Preparation",IF(H13<=I13,"Technical Skills","Personality & Communication")) -> Personality & Communication | X13: =IF(W13="Interview Preparation","Improve interview preparation and communication",IF(W13="Technical Skills","Strengthen technical skills and practical knowledge","Work on communication and personality development")) -> Work on communication and personality development
... A1501: 34 | B1501: 1 | C1501: 2 | D1501: 11 | E1501: 5 | F1501: 12.910472 | G1501: 63 | H1501: 40 | I1501: 26 | J1501: 2 | K1501: 1 | L1501: ="C"&TEXT(ROW()-1,"000") -> C1500 | M1501: =IF(B1501=0,"Male","Female") -> Female | N1501: =IF(C1501=1,"Bachelor's Type 1",IF(C1501=2,"Bachelor's Type 2",IF(C1501=3,"Master's","PhD"))) -> Bachelor's Type 2 | O1501: =IF(D1501<=2,"Entry Level",IF(D1501<=6,"Mid Level","Senior Level")) -> Senior Level | P1501: =IF(G1501<50,"Low",IF(G1501<75,"Average","Strong")) -> Average | Q1501: =IF(H1501<50,"Beginner",IF(H1501<75,"Intermediate","Advanced")) -> Beginner | R1501: =IF(I1501<50,"Needs Improvement",IF(I1501<75,"Good","Strong")) -> Needs Improvement | S1501: =IF(K1501=1,"Hired","Not Hired") -> Hired | T1501: =ROUND((G1501*30%)+(H1501*30%)+(I1501*20%)+((D1501/15)*100*15%)+(IF(C1501<=2,50,IF(C1501=3,75,100))*5%),0) -> 50 | U1501: =IF(T1501<50,"Needs Improvement",IF(T1501<75,"Developing","Job Ready")) -> Developing | V1501: =IF(AND(G1501>=H1501,G1501>=I1501),"Interview",IF(H1501>=I1501,"Technical Skills","Personality")) -> Interview | W1501: =IF(AND(G1501<=H1501,G1501<=I1501),"Interview Preparation",IF(H1501<=I1501,"Technical Skills","Personality & Communication")) -> Personality & Communication | X1501: =IF(W1501="Interview Preparation","Improve interview preparation and communication",IF(W1501="Technical Skills","Strengthen technical skills and practical knowledge","Work on communication and personality development")) -> Work on communication and personality development

Sheet HireMao_Dashboard
A1: HireMap_Dashboard
A2: Candidate Hiring & Readiness Intelligence
A4: Total Candidates | D4: Hired Candidates | G4: Hiring Rate | J4: Avg Readiness Score | M4: Needs Improvement
A5: =COUNTA(recruitment_data!A2:A1501) -> 1500 | D5: =COUNTIF(recruitment_data!K2:K1501,1) -> 465 | G5: =D5/A5 -> 0.31 | J5: =AVERAGE(recruitment_data!T2:T1501) -> 51.102667 | M5: =COUNTIF(recruitment_data!U2:U1501,"Needs Improvement") -> 672
A63: Key Insights
A65: 1. Overall Hiring Performance
A67: Total 1,500 candidates were evaluated.
A69: Out of these, 465 candidates were hired, resulting in a 31% hiring rate.
A71: This indicates that the organization follows a selective recruitment process, with nearly 69% of applicants not being selected.
A75: 2. Candidate Readiness
A77: The average readiness score is 51.10, which is around the midpoint of the readiness scale.
A79: This suggests that most candidates require additional training or skill enhancement before becoming fully job-ready.
A83: 3. Recruitment Strategy Effectiveness
A85: Job Portal is the most effective recruitment source, attracting 770 candidates, making it the primary hiring channel.
A87: Walk-in Drives contributed 445 candidates, showing moderate effectiveness.
A89: Campus Drives generated only 285 candidates, indicating comparatively lower contribution.
... A177: Continue emphasizing technical and interview skill assessments, as these are key indicators of hiring success.

Sheet Analysis
A1: Metric | B1: Value
A2: Total Candidates | B2: =COUNTA(recruitment_data!A2:A1502) -> 1500
A3: Total Hired | B3: =COUNTIF(recruitment_data!S2:S1502,"Hired") -> 465
A4: Total Not Hired | B4: =COUNTIF(recruitment_data!S2:S1502,"Not Hired") -> 1035
A5: Hiring Rate | B5: =COUNTIF(recruitment_data!S2:S1502,"Hired")/COUNTA(recruitment_data!A2:A1502) -> 0.31
A6: Average Interview Score | B6: =AVERAGE(recruitment_data!G2:G1502) -> 50.564
A7: Average Skill Score | B7: =AVERAGE(recruitment_data!H2:H1502) -> 51.116
A8: Average Personality Score | B8: =AVERAGE(recruitment_data!I2:I1502) -> 49.387333
A9: Average Readiness Score | B9: =AVERAGE(recruitment_data!T2:T1502) -> 51.102667
A14: Metric | B14: Hired | C14: Not Hired | D14: Difference
A15: Candidate Count | B15: =COUNTIF(recruitment_data!S2:S1502,"Hired") -> 465 | C15: =COUNTIF(recruitment_data!S2:S1502,"Not Hired") -> 1035 | D15: =C15-B15 -> 570
A16: Avg Interview Score | B16: =AVERAGEIF(recruitment_data!S2:S1502,"Hired",recruitment_data!G2:G1502) -> 56.8 | C16: =AVERAGEIF(recruitment_data!S2:S1502,"Not Hired",recruitment_data!G2:G1502) -> 47.762319 | D16: =ABS(C16-B16) -> 9.0376812
A17: Avg Skill Score | B17: =AVERAGEIF(recruitment_data!S2:S1502,"Hired",recruitment_data!H2:H1502) -> 60.032258 | C17: =AVERAGEIF(recruitment_data!S2:S1502,"Not Hired",recruitment_data!H2:H1502) -> 47.110145 | D17: =ABS(C17-B17) -> 12.922113
A18: Avg Personality Score | B18: =AVERAGEIF(recruitment_data!S2:S1502,"Hired",recruitment_data!I2:I1502) -> 56.793548 | C18: =AVERAGEIF(recruitment_data!S2:S1502,"Not Hired",recruitment_data!I2:I1502) -> 46.059903 | D18: =ABS(C18-B18) -> 10.733645
A19: Avg Experience | B19: =AVERAGEIF(recruitment_data!S2:S1502,"Hired",recruitment_data!D2:D1502) -> 8.5419355 | C19: =AVERAGEIF(recruitment_data!S2:S1502,"Not Hired",recruitment_data!D2:D1502) -> 7.3130435 | D19: =ABS(C19-B19) -> 1.228892
A20: Avg Readiness Score | B20: =AVERAGEIF(recruitment_data!S2:S1502,"Hired",recruitment_data!T2:T1502) -> 58.288172 | C20: =AVERAGEIF(recruitment_data!S2:S1502,"Not Hired",recruitment_data!T2:T1502) -> 47.874396 | D20: =ABS(C20-B20) -> 10.413776
A24: Technical Skill Level | B24: Total Candidates | C24: Hired | D24: Not Hired | E24: Hiring Rate
A25: Beginner | B25: =COUNTIF(recruitment_data!Q2:Q1502,A25) -> 697 | C25: =COUNTIFS(recruitment_data!Q2:Q1502,A25,recruitment_data!S2:S1502,"Hired") -> 144 | D25: =COUNTIFS(recruitment_data!Q2:Q1502,A25,recruitment_data!S2:S1502,"Not Hired") -> 553 | E25: =C25/B25 -> 0.20659971
A26: Intermediate | B26: =COUNTIF(recruitment_data!Q3:Q1503,A26) -> 395 | C26: =COUNTIFS(recruitment_data!Q3:Q1503,A26,recruitment_data!S3:S1503,"Hired") -> 152 | D26: =COUNTIFS(recruitment_data!Q3:Q1503,A26,recruitment_data!S3:S1503,"Not Hired") -> 243 | E26: =C26/B26 -> 0.38481013
A27: Advanced | B27: =COUNTIF(recruitment_data!Q4:Q1504,A27) -> 407 | C27: =COUNTIFS(recruitment_data!Q4:Q1504,A27,recruitment_data!S4:S1504,"Hired") -> 168 | D27: =COUNTIFS(recruitment_data!Q4:Q1504,A27,recruitment_data!S4:S1504,"Not Hired") -> 239 | E27: =C27/B27 -> 0.41277641
A30: Readiness Category | B30: Total Candidates | C30: Hired | D30: Not Hired | E30: Hiring Rate
A31: Needs Improvement | B31: =COUNTIF(recruitment_data!U2:U1502,A31) -> 672 | C31: =COUNTIFS(recruitment_data!U2:U1502,A31,recruitment_data!S2:S1502,"Hired") -> 107 | D31: =COUNTIFS(recruitment_data!U2:U1502,A31,recruitment_data!S2:S1502,"Not Hired") -> 565 | E31: =C31/B31 -> 0.15922619
A32: Developing | B32: =COUNTIF(recruitment_data!U3:U1503,A32) -> 758 | C32: =COUNTIFS(recruitment_data!U3:U1503,A32,recruitment_data!S3:S1503,"Hired") -> 302 | D32: =COUNTIFS(recruitment_data!U3:U1503,A32,recruitment_data!S3:S1503,"Not Hired") -> 456 | E32: =C32/B32 -> 0.39841689
A33: Job Ready | B33: =COUNTIF(recruitment_data!U4:U1504,A33) -> 69 | C33: =COUNTIFS(recruitment_data!U4:U1504,A33,recruitment_data!S4:S1504,"Hired") -> 55 | D33: =COUNTIFS(recruitment_data!U4:U1504,A33,recruitment_data!S4:S1504,"Not Hired") -> 14 | E33: =C33/B33 -> 0.79710145

Sheet primaryS.Pivot
A1: Count of Candidate_id | B1: Hiring_Decision_Name
A2: Primary Strength | B2: Hired | C2: Not Hired | D2: Grand Total
A3: Interview | B3: 167 | C3: 357 | D3: 524
A4: Personality | B4: 144 | C4: 326 | D4: 470
A5: Technical Skills | B5: 154 | C5: 352 | D5: 506
A6: Grand Total | B6: 465 | C6: 1035 | D6: 1500
A14: Count of Candidate_id | B14: Hiring_Decision_Name
A15: Primary Gap | B15: Hired | C15: Not Hired | D15: Grand Total | E15: Hiring Rate
A16: Interview Preparation | B16: 90 | C16: 166 | D16: 256 | E16: 0.3307
A17: Personality & Communication | B17: 70 | C17: 166 | D17: 236 | E17: 0.3108
A18: Technical Skills | B18: 68 | C18: 178 | D18: 246 | E18: 0.2878
A19: Grand Total | B19: 228 | C19: 510 | D19: 738 | E19: 0.31
A23: Readiness_Category | B23: Count of Candidate_id | C23: Average of Candidate_Readiness_Score
A24: Developing | B24: 375 | C24: 59.624
A25: Job Ready | B25: 34 | C25: 79.058824
A26: Needs Improvement | B26: 329 | C26: 38.37386
A27: Grand Total | B27: 738 | C27: 51.04607
A31: Count of Candidate_id | B31: Hiring_Decision_Name
A32: Readiness_Category | B32: Hired | C32: Not Hired | D32: Grand Total
A33: Developing | B33: 143 | C33: 232 | D33: 375
A34: Job Ready | B34: 31 | C34: 3 | D34: 34
A35: Needs Improvement | B35: 54 | C35: 275 | D35: 329
A36: Grand Total | B36: 228 | C36: 510 | D36: 738
A41: Readiness Category | B41: Hired | C41: Not Hired | D41: Total | E41: Hiring Rate
A42: Job Ready | B42: 55 | C42: 14 | D42: 69 | E42: 0.7971
A43: Developing | B43: 303 | C43: 456 | D43: 759 | E43: 0.3992
A44: Needs Improvement | B44: 107 | C44: 565 | D44: 672 | E44: 0.1592
A45: Overall | B45: 465 | C45: 1035 | D45: 1500 | E45: 0.31
A48: Count of Candidate_id | B48: Hiring_Decision_Name
A49: Experience_Level | B49: Hired | C49: Not Hired | D49: Grand Total
A50: Entry Level | B50: 29 | C50: 107 | D50: 136
A51: Mid Level | B51: 48 | C51: 127 | D51: 175
A52: Senior Level | B52: 151 | C52: 276 | D52: 427
A53: Grand Total | B53: 228 | C53: 510 | D53: 738
A55: Experience Level | B55: Hired | C55: Not Hired | D55: Total | E55: Hiring Rate
A56: Entry Level | B56: 52 | C56: 218 | D56: 270 | E56: 0.1926
A57: Mid Level | B57: 97 | C57: 262 | D57: 359 | E57: 0.2702
A58: Senior Level | B58: 316 | C58: 555 | D58: 871 | E58: 0.3628
A59: Overall | B59: 465 | C59: 1035 | D59: 1500 | E59: 0.31
A61: Count of Candidate_id | B61: Hiring_Decision_Name
...
